<?xml version="1.0" encoding="UTF-8"?>
<!-- Generated by org.testng.reporters.JUnitReportReporter -->
<testsuite hostname="MIIPL_ON_Rajendra_Mane" failures="0" tests="2" name="SOR_testcases.SOR_LoginTestCase" time="28.720" errors="1" timestamp="2025-02-13T16:50:44 IST" skipped="1">
  <testcase classname="SOR_testcases.SOR_LoginTestCase" name="Initalization" time="28.720">
    <error message="[Execute Error] Unable to connect to the hlm-backend service. Please check if the service is up and running, and verify that the connection URL is correct." type="com.epam.healenium.exception.HealeniumException">
      <![CDATA[com.epam.healenium.exception.HealeniumException: [Execute Error] Unable to connect to the hlm-backend service. Please check if the service is up and running, and verify that the connection URL is correct.
at com.epam.healenium.client.RestClient.serverExecute(RestClient.java:271)
at com.epam.healenium.client.RestClient.getElements(RestClient.java:137)
at com.epam.healenium.SelfHealingEngine.loadStoredSelectors(SelfHealingEngine.java:169)
at com.epam.healenium.SelfHealingDriver.callInitActions(SelfHealingDriver.java:65)
at com.epam.healenium.SelfHealingDriver.create(SelfHealingDriver.java:42)
at SOR_testcases.Base.launchBrowser(Base.java:112)
at SOR_testcases.SOR_LoginTestCase.Initalization(SOR_LoginTestCase.java:24)
at java.base/jdk.internal.reflect.DirectMethodHandleAccessor.invoke(DirectMethodHandleAccessor.java:103)
at java.base/java.lang.reflect.Method.invoke(Method.java:580)
at org.testng.internal.MethodInvocationHelper.invokeMethod(MethodInvocationHelper.java:133)
at org.testng.internal.MethodInvocationHelper.invokeMethodConsideringTimeout(MethodInvocationHelper.java:62)
at org.testng.internal.ConfigInvoker.invokeConfigurationMethod(ConfigInvoker.java:385)
at org.testng.internal.ConfigInvoker.invokeConfigurations(ConfigInvoker.java:321)
at org.testng.internal.TestMethodWorker.invokeBeforeClassMethods(TestMethodWorker.java:176)
at org.testng.internal.TestMethodWorker.run(TestMethodWorker.java:122)
at java.base/java.util.ArrayList.forEach(ArrayList.java:1596)
at org.testng.TestRunner.privateRun(TestRunner.java:794)
at org.testng.TestRunner.run(TestRunner.java:596)
at org.testng.SuiteRunner.runTest(SuiteRunner.java:377)
at org.testng.SuiteRunner.runSequentially(SuiteRunner.java:371)
at org.testng.SuiteRunner.privateRun(SuiteRunner.java:332)
at org.testng.SuiteRunner.run(SuiteRunner.java:276)
at org.testng.SuiteRunnerWorker.runSuite(SuiteRunnerWorker.java:53)
at org.testng.SuiteRunnerWorker.run(SuiteRunnerWorker.java:96)
at org.testng.TestNG.runSuitesSequentially(TestNG.java:1212)
at org.testng.TestNG.runSuitesLocally(TestNG.java:1134)
at org.testng.TestNG.runSuites(TestNG.java:1063)
at org.testng.TestNG.run(TestNG.java:1031)
at org.testng.remote.AbstractRemoteTestNG.run(AbstractRemoteTestNG.java:115)
at org.testng.remote.RemoteTestNG.initAndRun(RemoteTestNG.java:293)
at org.testng.remote.RemoteTestNG.main(RemoteTestNG.java:91)
Caused by: java.io.UncheckedIOException: java.net.ConnectException
at org.openqa.selenium.remote.http.jdk.JdkHttpClient.execute0(JdkHttpClient.java:497)
at org.openqa.selenium.remote.http.AddSeleniumUserAgent.lambda$apply$0(AddSeleniumUserAgent.java:42)
at org.openqa.selenium.remote.http.Filter.lambda$andFinally$1(Filter.java:55)
at org.openqa.selenium.remote.http.jdk.JdkHttpClient.lambda$executeAsync$1(JdkHttpClient.java:384)
at java.base/java.util.concurrent.Executors$RunnableAdapter.call(Executors.java:572)
at java.base/java.util.concurrent.FutureTask.run(FutureTask.java:317)
at java.base/java.util.concurrent.ThreadPoolExecutor.runWorker(ThreadPoolExecutor.java:1144)
at java.base/java.util.concurrent.ThreadPoolExecutor$Worker.run(ThreadPoolExecutor.java:642)
at java.base/java.lang.Thread.run(Thread.java:1583)
Caused by: java.net.ConnectException
at java.net.http/jdk.internal.net.http.HttpClientImpl.send(HttpClientImpl.java:951)
at java.net.http/jdk.internal.net.http.HttpClientFacade.send(HttpClientFacade.java:133)
at org.openqa.selenium.remote.http.jdk.JdkHttpClient.execute0(JdkHttpClient.java:456)
... 8 more
Caused by: java.net.ConnectException
at java.net.http/jdk.internal.net.http.common.Utils.toConnectException(Utils.java:1028)
at java.net.http/jdk.internal.net.http.PlainHttpConnection.connectAsync(PlainHttpConnection.java:227)
at java.net.http/jdk.internal.net.http.PlainHttpConnection.checkRetryConnect(PlainHttpConnection.java:280)
at java.net.http/jdk.internal.net.http.PlainHttpConnection.lambda$connectAsync$2(PlainHttpConnection.java:238)
at java.base/java.util.concurrent.CompletableFuture.uniHandle(CompletableFuture.java:934)
at java.base/java.util.concurrent.CompletableFuture$UniHandle.tryFire(CompletableFuture.java:911)
at java.base/java.util.concurrent.CompletableFuture.postComplete(CompletableFuture.java:510)
at java.base/java.util.concurrent.CompletableFuture$AsyncSupply.run(CompletableFuture.java:1773)
... 3 more
Caused by: java.nio.channels.ClosedChannelException
at java.base/sun.nio.ch.SocketChannelImpl.ensureOpen(SocketChannelImpl.java:202)
at java.base/sun.nio.ch.SocketChannelImpl.beginConnect(SocketChannelImpl.java:786)
at java.base/sun.nio.ch.SocketChannelImpl.connect(SocketChannelImpl.java:874)
at java.net.http/jdk.internal.net.http.PlainHttpConnection.lambda$connectAsync$1(PlainHttpConnection.java:210)
at java.base/java.security.AccessController.doPrivileged(AccessController.java:571)
at java.net.http/jdk.internal.net.http.PlainHttpConnection.connectAsync(PlainHttpConnection.java:212)
... 9 more
]]>
    </error>
  </testcase> <!-- Initalization -->
  <system-out/>
  <testcase classname="SOR_testcases.SOR_LoginTestCase" name="Check_Valid_Credentials" time="0.000">
    <skipped/>
  </testcase> <!-- Check_Valid_Credentials -->
  <system-out/>
</testsuite> <!-- SOR_testcases.SOR_LoginTestCase -->
